Input Notebook:  training_mT5_small.ipynb
Output Notebook: ./papermill/run_001_training_mT5_small.ipynb
Executing:   0%|          | 0/46 [00:00<?, ?cell/s]Executing notebook with kernel: python3
Executing:   2%|▏         | 1/46 [00:01<00:47,  1.05s/cell]Executing:   4%|▍         | 2/46 [00:01<00:27,  1.59cell/s]Executing:  11%|█         | 5/46 [00:01<00:08,  4.92cell/s]Executing:  17%|█▋        | 8/46 [00:01<00:04,  8.51cell/s]Executing:  24%|██▍       | 11/46 [00:02<00:05,  6.65cell/s]Executing:  30%|███       | 14/46 [00:03<00:07,  4.29cell/s]Executing:  35%|███▍      | 16/46 [00:04<00:11,  2.59cell/s]Executing:  41%|████▏     | 19/46 [00:05<00:07,  3.86cell/s]Executing:  41%|████▏     | 19/46 [00:20<00:07,  3.86cell/s]Executing:  43%|████▎     | 20/46 [00:41<02:25,  5.61s/cell]Executing:  50%|█████     | 23/46 [00:41<01:19,  3.46s/cell]Executing:  57%|█████▋    | 26/46 [00:42<00:44,  2.25s/cell]Executing:  63%|██████▎   | 29/46 [00:42<00:25,  1.50s/cell]Executing:  63%|██████▎   | 29/46 [01:00<00:25,  1.50s/cell]Executing:  65%|██████▌   | 30/46 [01:19<01:42,  6.43s/cell]Executing:  70%|██████▉   | 32/46 [01:19<01:04,  4.63s/cell]Executing:  76%|███████▌  | 35/46 [01:19<00:31,  2.90s/cell]Executing:  80%|████████  | 37/46 [01:22<00:23,  2.57s/cell]Executing:  83%|████████▎ | 38/46 [01:40<00:20,  2.57s/cell]wandb: Network error (ReadTimeout), entering retry loop.
wandb: ERROR Error while calling W&B API: internal database error (<Response [500]>)
Executing:  83%|████████▎ | 38/46 [4:25:00<55:47, 418.44s/cell]
Traceback (most recent call last):
  File "/home/ubuntu/anaconda3/envs/transformers/lib/python3.9/site-packages/papermill/engines.py", line 359, in execute_notebook
    cls.execute_managed_notebook(nb_man, kernel_name, log_output=log_output, **kwargs)
  File "/home/ubuntu/anaconda3/envs/transformers/lib/python3.9/site-packages/papermill/engines.py", line 418, in execute_managed_notebook
    return PapermillNotebookClient(nb_man, **final_kwargs).execute()
  File "/home/ubuntu/anaconda3/envs/transformers/lib/python3.9/site-packages/papermill/clientwrap.py", line 45, in execute
    self.papermill_execute_cells()
  File "/home/ubuntu/anaconda3/envs/transformers/lib/python3.9/site-packages/papermill/clientwrap.py", line 77, in papermill_execute_cells
    self.nb_man.cell_complete(self.nb.cells[index], cell_index=index)
  File "/home/ubuntu/anaconda3/envs/transformers/lib/python3.9/site-packages/papermill/engines.py", line 69, in wrapper
    return func(self, *args, **kwargs)
  File "/home/ubuntu/anaconda3/envs/transformers/lib/python3.9/site-packages/papermill/engines.py", line 260, in cell_complete
    self.save()
  File "/home/ubuntu/anaconda3/envs/transformers/lib/python3.9/site-packages/papermill/engines.py", line 69, in wrapper
    return func(self, *args, **kwargs)
  File "/home/ubuntu/anaconda3/envs/transformers/lib/python3.9/site-packages/papermill/engines.py", line 139, in save
    write_ipynb(self.nb, self.output_path)
  File "/home/ubuntu/anaconda3/envs/transformers/lib/python3.9/site-packages/papermill/iorw.py", line 447, in write_ipynb
    papermill_io.write(nbformat.writes(nb), path)
  File "/home/ubuntu/anaconda3/envs/transformers/lib/python3.9/site-packages/papermill/iorw.py", line 143, in write
    return self.get_handler(path).write(buf, path)
  File "/home/ubuntu/anaconda3/envs/transformers/lib/python3.9/site-packages/papermill/iorw.py", line 228, in write
    f.write(buf)
OSError: [Errno 28] No space left on device

During handling of the above exception, another exception occurred:

Traceback (most recent call last):
  File "/home/ubuntu/anaconda3/envs/transformers/bin/papermill", line 10, in <module>
    sys.exit(papermill())
  File "/home/ubuntu/anaconda3/envs/transformers/lib/python3.9/site-packages/click/core.py", line 1130, in __call__
    return self.main(*args, **kwarg